Workbook

Sheet About
A1: Hospital Analytics 2023 - cleaned data & measures
A2: VOLTIX Data Analyst track - Task 7
A4: Sheet | B4: Contents
A5: KPIs | B5: 19 headline measures (volume, efficiency, acuity, finance, data quality) - each with formula logic and purpose.
A6: Summary Tables | B6: Admissions, ALOS, bed-days, long-stay, severity, uninsured and billing measures by 10 dimensions.
A7: Severity x Dx | B7: Severity mix per diagnosis - shows the severity field does not line up with diagnosis or stay length.
A8: Daily Census | B8: Patients in a bed each night of 2023 - capacity view behind Avg / Peak census.
A9: Clean Data | B9: 247 cleaned admissions (Excel Table 'tblPatients') with 34 columns incl. calculated columns.
A10: Cleaning Log | B10: Every check, rows affected and action taken (duplicates, reversed dates, placeholder bills...).
A11: Data Dictionary | B11: Meaning and origin of every column.
A12: Raw Data | B12: The original sheet, unchanged, for audit.
A14: Key cleaning decisions
A15: - 1 exact duplicate removed; 29 reversed admission/discharge dates swapped (flagged in Date_Corrected).
A16: - Bills of 999 (x100) and 3852 (x95) are system placeholders: identical across every diagnosis, severity and stay length,
A17: while the 52 genuine bills rise with stay length (r = 0.64). They are blanked, not imputed; Bill_Raw keeps the original.
A18: - Unusual but possible values are flagged, not deleted (long stays for minor conditions, atypical ages).
A19: Full dashboard: Hospital_Dashboard.html. Insights: KEY_INSIGHTS.md.

Sheet KPIs
A1: Hospital performance - KPIs & measures
A2: Every value is a live formula over the 'Clean Data' sheet (247 admissions, 2023). Edit the data and they update.
A4: Area | B4: KPI / measure | C4: Value | D4: How it is calculated | E4: Why it matters (question it answers)
A5: Volume | B5: Total admissions | C5: =COUNTA('Clean Data'!$A$2:$A$248) -> 247 | D5: Count of admission records after removing the duplicate | E5: How much demand does the hospital serve?
A6: Volume | B6: Admissions per doctor | C6: =C5/SUMPRODUCT(1/COUNTIF('Clean Data'!$J$2:$J$248,'Clean Data'!$J$2:$J$248)) -> 35.285714 | D6: Admissions / number of distinct doctors | E6: Is the workload spread evenly across the 7 doctors?
A7: Volume | B7: Average daily census | C7: =(SUMPRODUCT(('Clean Data'!$M$2:$M$248<=DATE(2024,1,1))*'Clean Data'!$M$2:$M$248+('Clean Data'!$M$2:$M$248>DATE(2024,1,1))*DATE(2024,1,1))-SUMPRODUCT(('Clean Data'!$L$2:$L$248>=DATE(2023,1,1))*'Clean Data'!$L$2:$L$248+('Clean Data'!$L$2:$L$248<DATE(2023,1,1))*DATE(2023,1,1)))/365 -> 4.1589041 | D7: Occupied bed-nights inside 2023 / 365 | E7: How many beds are needed on a normal day?
A8: Volume | B8: Peak daily census | C8: =MAX('Daily Census'!B5:B383) -> 13 | D8: Highest value on the Daily Census sheet | E8: Capacity needed on the busiest night - size beds and staff for this.
A9: Efficiency | B9: Average length of stay (ALOS, days) | C9: =AVERAGE('Clean Data'!$N$2:$N$248) -> 6.2631579 | D9: Mean of Discharge - Admission | E9: Core efficiency measure: lower ALOS frees beds.
A10: Efficiency | B10: Median length of stay (days) | C10: =MEDIAN('Clean Data'!$N$2:$N$248) -> 4 | D10: Middle stay length | E10: Typical patient - the gap to ALOS shows how much long stays pull the average.
A11: Efficiency | B11: Total bed-days | C11: =SUM('Clean Data'!$N$2:$N$248) -> 1547 | D11: Sum of all stay lengths | E11: Total bed capacity consumed.
A12: Efficiency | B12: Long-stay rate (> 7 days) | C12: =COUNTIF('Clean Data'!$P$2:$P$248,TRUE())/C5 -> 0.25506073 | D12: Share of admissions with stay > 7 days | E12: How many patients become bed-blockers?
A13: Efficiency | B13: Bed-days used by 15+ day stays | C13: =SUMIF('Clean Data'!$N$2:$N$248,">=15")/C11 -> 0.34712346 | D13: Bed-days of stays >= 15 days / all bed-days | E13: How much capacity a small group of very long stays absorbs.
A14: Acuity | B14: High-severity share | C14: =COUNTIF('Clean Data'!$AB$2:$AB$248,TRUE())/C5 -> 0.36032389 | D14: Admissions marked High severity / all | E14: How acute is the case mix?
A15: Acuity | B15: Senior patients share (60+) | C15: =COUNTIF('Clean Data'!$C$2:$C$248,">=60")/C5 -> 0.36032389 | D15: Admissions aged 60+ / all | E15: Older patients stay longer - drives geriatric resource planning.
A16: Acuity | B16: Average patient age | C16: =AVERAGE('Clean Data'!$C$2:$C$248) -> 47.417004 | D16: Mean age | E16: Who the hospital mainly serves.
A17: Finance | B17: Uninsured rate | C17: =COUNTIF('Clean Data'!$Y$2:$Y$248,TRUE())/C5 -> 0.29149798 | D17: Admissions with no insurance / all | E17: Share of revenue exposed to non-payment.
A18: Finance | B18: Billing completeness | C18: =COUNT('Clean Data'!$AC$2:$AC$248)/C5 -> 0.21052632 | D18: Admissions with a genuine bill / all (999 & 3852 placeholders excluded) | E18: Can revenue be reported at all? (target: 100%)
A19: Finance | B19: Average recorded bill | C19: =AVERAGE('Clean Data'!$AC$2:$AC$248) -> 2945.2885 | D19: Mean of genuine bills only | E19: Typical charge per admission (indicative - short stays only).
A20: Finance | B20: Median bill per bed-day | C20: =MEDIAN('Clean Data'!$AF$2:$AF$248) -> 784.5 | D20: Median of Bill / Length_of_Stay on genuine bills | E20: Unit price of a bed-day - use to estimate lost revenue.
A21: Finance | B21: Total recorded billing | C21: =SUM('Clean Data'!$AC$2:$AC$248) -> 153155 | D21: Sum of genuine bills | E21: Revenue that is actually documented.
A22: Data quality | B22: Date-correction rate | C22: =COUNTIF('Clean Data'!$AG$2:$AG$248,TRUE())/C5 -> 0.11740891 | D22: Rows whose admission/discharge dates were reversed | E22: Reliability of the admission system's date entry.
A23: Data quality | B23: Records flagged for clinical review | C23: =COUNTIF('Clean Data'!$AH$2:$AH$248,"?*")/C5 -> 0.097165992 | D23: Long stay for a minor condition, or atypical age for diagnosis | E23: Coding / care-pathway audit workload.
A25: Note: 195 of 247 bills held the placeholder values 999 or 3852 (see Cleaning Log). They are excluded, so every finance KPI describes the 52 genuine bills - almost all short stays - and understates the true average charge.

Sheet Summary Tables
A1: Summary tables
A2: COUNTIFS / AVERAGEIFS / SUMIFS measures over the Clean Data sheet - one block per dimension.
A4: By diagnosis
A5: Diagnosis | B5: Admissions | C5: % of admissions | D5: ALOS (days) | E5: Bed-days | F5: % of bed-days | G5: Long-stay rate | H5: High-severity share | I5: Uninsured rate | J5: Genuine bills | K5: Avg genuine bill | L5: Clinical review flags
A6: Influenza | B6: =COUNTIFS('Clean Data'!$G$2:$G$248,$A6) -> 40 | C6: =B6/COUNTA('Clean Data'!$A$2:$A$248) -> 0.16194332 | D6: =IFERROR(AVERAGEIFS('Clean Data'!$N$2:$N$248,'Clean Data'!$G$2:$G$248,$A6),"") -> 6.275 | E6: =SUMIFS('Clean Data'!$N$2:$N$248,'Clean Data'!$G$2:$G$248,$A6) -> 251 | F6: =E6/SUM('Clean Data'!$N$2:$N$248) -> 0.16224952 | G6: =IFERROR(COUNTIFS('Clean Data'!$G$2:$G$248,$A6,'Clean Data'!$P$2:$P$248,TRUE())/B6,"") -> 0.3 | H6: =IFERROR(COUNTIFS('Clean Data'!$G$2:$G$248,$A6,'Clean Data'!$AB$2:$AB$248,TRUE())/B6,"") -> 0.325 | I6: =IFERROR(COUNTIFS('Clean Data'!$G$2:$G$248,$A6,'Clean Data'!$Y$2:$Y$248,TRUE())/B6,"") -> 0.25 | J6: =COUNTIFS('Clean Data'!$G$2:$G$248,$A6,'Clean Data'!$AC$2:$AC$248,"<>") -> 8 | K6: =IFERROR(AVERAGEIFS('Clean Data'!$AC$2:$AC$248,'Clean Data'!$G$2:$G$248,$A6),"-") -> 2560.5 | L6: =COUNTIFS('Clean Data'!$G$2:$G$248,$A6,'Clean Data'!$AH$2:$AH$248,"?*") -> 4
A7: Fractures | B7: =COUNTIFS('Clean Data'!$G$2:$G$248,$A7) -> 37 | C7: =B7/COUNTA('Clean Data'!$A$2:$A$248) -> 0.14979757 | D7: =IFERROR(AVERAGEIFS('Clean Data'!$N$2:$N$248,'Clean Data'!$G$2:$G$248,$A7),"") -> 5.1351351 | E7: =SUMIFS('Clean Data'!$N$2:$N$248,'Clean Data'!$G$2:$G$248,$A7) -> 190 | F7: =E7/SUM('Clean Data'!$N$2:$N$248) -> 0.12281836 | G7: =IFERROR(COUNTIFS('Clean Data'!$G$2:$G$248,$A7,'Clean Data'!$P$2:$P$248,TRUE())/B7,"") -> 0.13513514 | H7: =IFERROR(COUNTIFS('Clean Data'!$G$2:$G$248,$A7,'Clean Data'!$AB$2:$AB$248,TRUE())/B7,"") -> 0.27027027 | I7: =IFERROR(COUNTIFS('Clean Data'!$G$2:$G$248,$A7,'Clean Data'!$Y$2:$Y$248,TRUE())/B7,"") -> 0.24324324 | J7: =COUNTIFS('Clean Data'!$G$2:$G$248,$A7,'Clean Data'!$AC$2:$AC$248,"<>") -> 13 | K7: =IFERROR(AVERAGEIFS('Clean Data'!$AC$2:$AC$248,'Clean Data'!$G$2:$G$248,$A7),"-") -> 2799.4615 | L7: =COUNTIFS('Clean Data'!$G$2:$G$248,$A7,'Clean Data'!$AH$2:$AH$248,"?*") -> 0
A8: Chronic Allergy | B8: =COUNTIFS('Clean Data'!$G$2:$G$248,$A8) -> 34 | C8: =B8/COUNTA('Clean Data'!$A$2:$A$248) -> 0.13765182 | D8: =IFERROR(AVERAGEIFS('Clean Data'!$N$2:$N$248,'Clean Data'!$G$2:$G$248,$A8),"") -> 6.7941176 | E8: =SUMIFS('Clean Data'!$N$2:$N$248,'Clean Data'!$G$2:$G$248,$A8) -> 231 | F8: =E8/SUM('Clean Data'!$N$2:$N$248) -> 0.14932127 | G8: =IFERROR(COUNTIFS('Clean Data'!$G$2:$G$248,$A8,'Clean Data'!$P$2:$P$248,TRUE())/B8,"") -> 0.35294118 | H8: =IFERROR(COUNTIFS('Clean Data'!$G$2:$G$248,$A8,'Clean Data'!$AB$2:$AB$248,TRUE())/B8,"") -> 0.47058824 | I8: =IFERROR(COUNTIFS('Clean Data'!$G$2:$G$248,$A8,'Clean Data'!$Y$2:$Y$248,TRUE())/B8,"") -> 0.32352941 | J8: =COUNTIFS('Clean Data'!$G$2:$G$248,$A8,'Clean Data'!$AC$2:$AC$248,"<>") -> 4 | K8: =IFERROR(AVERAGEIFS('Clean Data'!$AC$2:$AC$248,'Clean Data'!$G$2:$G$248,$A8),"-") -> 1873.75 | L8: =COUNTIFS('Clean Data'!$G$2:$G$248,$A8,'Clean Data'!$AH$2:$AH$248,"?*") -> 4
A9: Common Cold | B9: =COUNTIFS('Clean Data'!$G$2:$G$248,$A9) -> 31 | C9: =B9/COUNTA('Clean Data'!$A$2:$A$248) -> 0.12550607 | D9: =IFERROR(AVERAGEIFS('Clean Data'!$N$2:$N$248,'Clean Data'!$G$2:$G$248,$A9),"") -> 7.7419355 | E9: =SUMIFS('Clean Data'!$N$2:$N$248,'Clean Data'!$G$2:$G$248,$A9) -> 240 | F9: =E9/SUM('Clean Data'!$N$2:$N$248) -> 0.15513898 | G9: =IFERROR(COUNTIFS('Clean Data'!$G$2:$G$248,$A9,'Clean Data'!$P$2:$P$248,TRUE())/B9,"") -> 0.32258065 | H9: =IFERROR(COUNTIFS('Clean Data'!$G$2:$G$248,$A9,'Clean Data'!$AB$2:$AB$248,TRUE())/B9,"") -> 0.48387097 | I9: =IFERROR(COUNTIFS('Clean Data'!$G$2:$G$248,$A9,'Clean Data'!$Y$2:$Y$248,TRUE())/B9,"") -> 0.32258065 | J9: =COUNTIFS('Clean Data'!$G$2:$G$248,$A9,'Clean Data'!$AC$2:$AC$248,"<>") -> 7 | K9: =IFERROR(AVERAGEIFS('Clean Data'!$AC$2:$AC$248,'Clean Data'!$G$2:$G$248,$A9),"-") -> 3118 | L9: =COUNTIFS('Clean Data'!$G$2:$G$248,$A9,'Clean Data'!$AH$2:$AH$248,"?*") -> 8
A10: Diabetes | B10: =COUNTIFS('Clean Data'!$G$2:$G$248,$A10) -> 28 | C10: =B10/COUNTA('Clean Data'!$A$2:$A$248) -> 0.11336032 | D10: =IFERROR(AVERAGEIFS('Clean Data'!$N$2:$N$248,'Clean Data'!$G$2:$G$248,$A10),"") -> 5.6428571 | E10: =SUMIFS('Clean Data'!$N$2:$N$248,'Clean Data'!$G$2:$G$248,$A10) -> 158 | F10: =E10/SUM('Clean Data'!$N$2:$N$248) -> 0.10213316 | G10: =IFERROR(COUNTIFS('Clean Data'!$G$2:$G$248,$A10,'Clean Data'!$P$2:$P$248,TRUE())/B10,"") -> 0.14285714 | H10: =IFERROR(COUNTIFS('Clean Data'!$G$2:$G$248,$A10,'Clean Data'!$AB$2:$AB$248,TRUE())/B10,"") -> 0.46428571 | I10: =IFERROR(COUNTIFS('Clean Data'!$G$2:$G$248,$A10,'Clean Data'!$Y$2:$Y$248,TRUE())/B10,"") -> 0.28571429 | J10: =COUNTIFS('Clean Data'!$G$2:$G$248,$A10,'Clean Data'!$AC$2:$AC$248,"<>") -> 5 | K10: =IFERROR(AVERAGEIFS('Clean Data'!$AC$2:$AC$248,'Clean Data'!$G$2:$G$248,$A10),"-") -> 3968.6 | L10: =COUNTIFS('Clean Data'!$G$2:$G$248,$A10,'Clean Data'!$AH$2:$AH$248,"?*") -> 0
A11: Hypertension | B11: =COUNTIFS('Clean Data'!$G$2:$G$248,$A11) -> 24 | C11: =B11/COUNTA('Clean Data'!$A$2:$A$248) -> 0.097165992 | D11: =IFERROR(AVERAGEIFS('Clean Data'!$N$2:$N$248,'Clean Data'!$G$2:$G$248,$A11),"") -> 5.7916667 | E11: =SUMIFS('Clean Data'!$N$2:$N$248,'Clean Data'!$G$2:$G$248,$A11) -> 139 | F11: =E11/SUM('Clean Data'!$N$2:$N$248) -> 0.089851325 | G11: =IFERROR(COUNTIFS('Clean Data'!$G$2:$G$248,$A11,'Clean Data'!$P$2:$P$248,TRUE())/B11,"") -> 0.16666667 | H11: =IFERROR(COUNTIFS('Clean Data'!$G$2:$G$248,$A11,'Clean Data'!$AB$2:$AB$248,TRUE())/B11,"") -> 0.20833333 | I11: =IFERROR(COUNTIFS('Clean Data'!$G$2:$G$248,$A11,'Clean Data'!$Y$2:$Y$248,TRUE())/B11,"") -> 0.16666667 | J11: =COUNTIFS('Clean Data'!$G$2:$G$248,$A11,'Clean Data'!$AC$2:$AC$248,"<>") -> 6 | K11: =IFERROR(AVERAGEIFS('Clean Data'!$AC$2:$AC$248,'Clean Data'!$G$2:$G$248,$A11),"-") -> 4533.1667 | L11: =COUNTIFS('Clean Data'!$G$2:$G$248,$A11,'Clean Data'!$AH$2:$AH$248,"?*") -> 6
A12: Kidney Failure | B12: =COUNTIFS('Clean Data'!$G$2:$G$248,$A12) -> 19 | C12: =B12/COUNTA('Clean Data'!$A$2:$A$248) -> 0.076923077 | D12: =IFERROR(AVERAGEIFS('Clean Data'!$N$2:$N$248,'Clean Data'!$G$2:$G$248,$A12),"") -> 6.4210526 | E12: =SUMIFS('Clean Data'!$N$2:$N$248,'Clean Data'!$G$2:$G$248,$A12) -> 122 | F12: =E12/SUM('Clean Data'!$N$2:$N$248) -> 0.078862314 | G12: =IFERROR(COUNTIFS('Clean Data'!$G$2:$G$248,$A12,'Clean Data'!$P$2:$P$248,TRUE())/B12,"") -> 0.31578947 | H12: =IFERROR(COUNTIFS('Clean Data'!$G$2:$G$248,$A12,'Clean Data'!$AB$2:$AB$248,TRUE())/B12,"") -> 0.26315789 | I12: =IFERROR(COUNTIFS('Clean Data'!$G$2:$G$248,$A12,'Clean Data'!$Y$2:$Y$248,TRUE())/B12,"") -> 0.36842105 | J12: =COUNTIFS('Clean Data'!$G$2:$G$248,$A12,'Clean Data'!$AC$2:$AC$248,"<>") -> 3 | K12: =IFERROR(AVERAGEIFS('Clean Data'!$AC$2:$AC$248,'Clean Data'!$G$2:$G$248,$A12),"-") -> 2461.3333 | L12: =COUNTIFS('Clean Data'!$G$2:$G$248,$A12,'Clean Data'!$AH$2:$AH$248,"?*") -> 0
A13: Migraine | B13: =COUNTIFS('Clean Data'!$G$2:$G$248,$A13) -> 15 | C13: =B13/COUNTA('Clean Data'!$A$2:$A$248) -> 0.060728745 | D13: =IFERROR(AVERAGEIFS('Clean Data'!$N$2:$N$248,'Clean Data'!$G$2:$G$248,$A13),"") -> 6.4 | E13: =SUMIFS('Clean Data'!$N$2:$N$248,'Clean Data'!$G$2:$G$248,$A13) -> 96 | F13: =E13/SUM('Clean Data'!$N$2:$N$248) -> 0.062055591 | G13: =IFERROR(COUNTIFS('Clean Data'!$G$2:$G$248,$A13,'Clean Data'!$P$2:$P$248,TRUE())/B13,"") -> 0.26666667 | H13: =IFERROR(COUNTIFS('Clean Data'!$G$2:$G$248,$A13,'Clean Data'!$AB$2:$AB$248,TRUE())/B13,"") -> 0.2 | I13: =IFERROR(COUNTIFS('Clean Data'!$G$2:$G$248,$A13,'Clean Data'!$Y$2:$Y$248,TRUE())/B13,"") -> 0.4 | J13: =COUNTIFS('Clean Data'!$G$2:$G$248,$A13,'Clean Data'!$AC$2:$AC$248,"<>") -> 2 | K13: =IFERROR(AVERAGEIFS('Clean Data'!$AC$2:$AC$248,'Clean Data'!$G$2:$G$248,$A13),"-") -> 1009.5 | L13: =COUNTIFS('Clean Data'!$G$2:$G$248,$A13,'Clean Data'!$AH$2:$AH$248,"?*") -> 1
A14: Stroke | B14: =COUNTIFS('Clean Data'!$G$2:$G$248,$A14) -> 11 | C14: =B14/COUNTA('Clean Data'!$A$2:$A$248) -> 0.044534413 | D14: =IFERROR(AVERAGEIFS('Clean Data'!$N$2:$N$248,'Clean Data'!$G$2:$G$248,$A14),"") -> 7.4545455 | E14: =SUMIFS('Clean Data'!$N$2:$N$248,'Clean Data'!$G$2:$G$248,$A14) -> 82 | F14: =E14/SUM('Clean Data'!$N$2:$N$248) -> 0.053005818 | G14: =IFERROR(COUNTIFS('Clean Data'!$G$2:$G$248,$A14,'Clean Data'!$P$2:$P$248,TRUE())/B14,"") -> 0.45454545 | H14: =IFERROR(COUNTIFS('Clean Data'!$G$2:$G$248,$A14,'Clean Data'!$AB$2:$AB$248,TRUE())/B14,"") -> 0.27272727 | I14: =IFERROR(COUNTIFS('Clean Data'!$G$2:$G$248,$A14,'Clean Data'!$Y$2:$Y$248,TRUE())/B14,"") -> 0.36363636 | J14: =COUNTIFS('Clean Data'!$G$2:$G$248,$A14,'Clean Data'!$AC$2:$AC$248,"<>") -> 3 | K14: =IFERROR(AVERAGEIFS('Clean Data'!$AC$2:$AC$248,'Clean Data'!$G$2:$G$248,$A14),"-") -> 3142 | L14: =COUNTIFS('Clean Data'!$G$2:$G$248,$A14,'Clean Data'!$AH$2:$AH$248,"?*") -> 1
A15: Pneumonia | B15: =COUNTIFS('Clean Data'!$G$2:$G$248,$A15) -> 8 | C15: =B15/COUNTA('Clean Data'!$A$2:$A$248) -> 0.032388664 | D15: =IFERROR(AVERAGEIFS('Clean Data'!$N$2:$N$248,'Clean Data'!$G$2:$G$248,$A15),"") -> 4.75 | E15: =SUMIFS('Clean Data'!$N$2:$N$248,'Clean Data'!$G$2:$G$248,$A15) -> 38 | F15: =E15/SUM('Clean Data'!$N$2:$N$248) -> 0.024563672 | G15: =IFERROR(COUNTIFS('Clean Data'!$G$2:$G$248,$A15,'Clean Data'!$P$2:$P$248,TRUE())/B15,"") -> 0.125 | H15: =IFERROR(COUNTIFS('Clean Data'!$G$2:$G$248,$A15,'Clean Data'!$AB$2:$AB$248,TRUE())/B15,"") -> 0.75 | I15: =IFERROR(COUNTIFS('Clean Data'!$G$2:$G$248,$A15,'Clean Data'!$Y$2:$Y$248,TRUE())/B15,"") -> 0.375 | J15: =COUNTIFS('Clean Data'!$G$2:$G$248,$A15,'Clean Data'!$AC$2:$AC$248,"<>") -> 1 | K15: =IFERROR(AVERAGEIFS('Clean Data'!$AC$2:$AC$248,'Clean Data'!$G$2:$G$248,$A15),"-") -> 1086 | L15: =COUNTIFS('Clean Data'!$G$2:$G$248,$A15,'Clean Data'!$AH$2:$AH$248,"?*") -> 0
A16: Total | B16: =SUM(B6:B15) -> 247 | C16: =SUM(C6:C15) -> 1 | D16: =E16/B16 -> 6.2631579 | E16: =SUM(E6:E15) -> 1547 | F16: =SUM(F6:F15) -> 1 | J16: =SUM(J6:J15) -> 52 | L16: =SUM(L6:L15) -> 24
A19: By diagnosis group
A20: Diagnosis group | B20: Admissions | C20: % of admissions | D20: ALOS (days) | E20: Bed-days | F20: % of bed-days | G20: Long-stay rate | H20: High-severity share | I20: Uninsured rate | J20: Genuine bills | K20: Avg genuine bill | L20: Clinical review flags
A21: Chronic disease | B21: =COUNTIFS('Clean Data'!$I$2:$I$248,$A21) -> 105 | C21: =B21/COUNTA('Clean Data'!$A$2:$A$248) -> 0.42510121 | D21: =IFERROR(AVERAGEIFS('Clean Data'!$N$2:$N$248,'Clean Data'!$I$2:$I$248,$A21),"") -> 6.1904762 | E21: =SUMIFS('Clean Data'!$N$2:$N$248,'Clean Data'!$I$2:$I$248,$A21) -> 650 | F21: =E21/SUM('Clean Data'!$N$2:$N$248) -> 0.42016807 | G21: =IFERROR(COUNTIFS('Clean Data'!$I$2:$I$248,$A21,'Clean Data'!$P$2:$P$248,TRUE())/B21,"") -> 0.24761905 | H21: =IFERROR(COUNTIFS('Clean Data'!$I$2:$I$248,$A21,'Clean Data'!$AB$2:$AB$248,TRUE())/B21,"") -> 0.37142857 | I21: =IFERROR(COUNTIFS('Clean Data'!$I$2:$I$248,$A21,'Clean Data'!$Y$2:$Y$248,TRUE())/B21,"") -> 0.28571429 | J21: =COUNTIFS('Clean Data'!$I$2:$I$248,$A21,'Clean Data'!$AC$2:$AC$248,"<>") -> 18 | K21: =IFERROR(AVERAGEIFS('Clean Data'!$AC$2:$AC$248,'Clean Data'!$I$2:$I$248,$A21),"-") -> 3440.0556 | L21: =COUNTIFS('Clean Data'!$I$2:$I$248,$A21,'Clean Data'!$AH$2:$AH$248,"?*") -> 10
A22: Respiratory infection | B22: =COUNTIFS('Clean Data'!$I$2:$I$248,$A22) -> 79 | C22: =B22/COUNTA('Clean Data'!$A$2:$A$248) -> 0.31983806 | D22: =IFERROR(AVERAGEIFS('Clean Data'!$N$2:$N$248,'Clean Data'!$I$2:$I$248,$A22),"") -> 6.6962025 | E22: =SUMIFS('Clean Data'!$N$2:$N$248,'Clean Data'!$I$2:$I$248,$A22) -> 529 | F22: =E22/SUM('Clean Data'!$N$2:$N$248) -> 0.34195217 | G22: =IFERROR(COUNTIFS('Clean Data'!$I$2:$I$248,$A22,'Clean Data'!$P$2:$P$248,TRUE())/B22,"") -> 0.29113924 | H22: =IFERROR(COUNTIFS('Clean Data'!$I$2:$I$248,$A22,'Clean Data'!$AB$2:$AB$248,TRUE())/B22,"") -> 0.43037975 | I22: =IFERROR(COUNTIFS('Clean Data'!$I$2:$I$248,$A22,'Clean Data'!$Y$2:$Y$248,TRUE())/B22,"") -> 0.29113924 | J22: =COUNTIFS('Clean Data'!$I$2:$I$248,$A22,'Clean Data'!$AC$2:$AC$248,"<>") -> 16 | K22: =IFERROR(AVERAGEIFS('Clean Data'!$AC$2:$AC$248,'Clean Data'!$I$2:$I$248,$A22),"-") -> 2712.25 | L22: =COUNTIFS('Clean Data'!$I$2:$I$248,$A22,'Clean Data'!$AH$2:$AH$248,"?*") -> 12
A23: Trauma | B23: =COUNTIFS('Clean Data'!$I$2:$I$248,$A23) -> 37 | C23: =B23/COUNTA('Clean Data'!$A$2:$A$248) -> 0.14979757 | D23: =IFERROR(AVERAGEIFS('Clean Data'!$N$2:$N$248,'Clean Data'!$I$2:$I$248,$A23),"") -> 5.1351351 | E23: =SUMIFS('Clean Data'!$N$2:$N$248,'Clean Data'!$I$2:$I$248,$A23) -> 190 | F23: =E23/SUM('Clean Data'!$N$2:$N$248) -> 0.12281836 | G23: =IFERROR(COUNTIFS('Clean Data'!$I$2:$I$248,$A23,'Clean Data'!$P$2:$P$248,TRUE())/B23,"") -> 0.13513514 | H23: =IFERROR(COUNTIFS('Clean Data'!$I$2:$I$248,$A23,'Clean Data'!$AB$2:$AB$248,TRUE())/B23,"") -> 0.27027027 | I23: =IFERROR(COUNTIFS('Clean Data'!$I$2:$I$248,$A23,'Clean Data'!$Y$2:$Y$248,TRUE())/B23,"") -> 0.24324324 | J23: =COUNTIFS('Clean Data'!$I$2:$I$248,$A23,'Clean Data'!$AC$2:$AC$248,"<>") -> 13 | K23: =IFERROR(AVERAGEIFS('Clean Data'!$AC$2:$AC$248,'Clean Data'!$I$2:$I$248,$A23),"-") -> 2799.4615 | L23: =COUNTIFS('Clean Data'!$I$2:$I$248,$A23,'Clean Data'!$AH$2:$AH$248,"?*") -> 0
A24: Neurological | B24: =COUNTIFS('Clean Data'!$I$2:$I$248,$A24) -> 26 | C24: =B24/COUNTA('Clean Data'!$A$2:$A$248) -> 0.10526316 | D24: =IFERROR(AVERAGEIFS('Clean Data'!$N$2:$N$248,'Clean Data'!$I$2:$I$248,$A24),"") -> 6.8461538 | E24: =SUMIFS('Clean Data'!$N$2:$N$248,'Clean Data'!$I$2:$I$248,$A24) -> 178 | F24: =E24/SUM('Clean Data'!$N$2:$N$248) -> 0.11506141 | G24: =IFERROR(COUNTIFS('Clean Data'!$I$2:$I$248,$A24,'Clean Data'!$P$2:$P$248,TRUE())/B24,"") -> 0.34615385 | H24: =IFERROR(COUNTIFS('Clean Data'!$I$2:$I$248,$A24,'Clean Data'!$AB$2:$AB$248,TRUE())/B24,"") -> 0.23076923 | I24: =IFERROR(COUNTIFS('Clean Data'!$I$2:$I$248,$A24,'Clean Data'!$Y$2:$Y$248,TRUE())/B24,"") -> 0.38461538 | J24: =COUNTIFS('Clean Data'!$I$2:$I$248,$A24,'Clean Data'!$AC$2:$AC$248,"<>") -> 5 | K24: =IFERROR(AVERAGEIFS('Clean Data'!$AC$2:$AC$248,'Clean Data'!$I$2:$I$248,$A24),"-") -> 2289 | L24: =COUNTIFS('Clean Data'!$I$2:$I$248,$A24,'Clean Data'!$AH$2:$AH$248,"?*") -> 2
A25: Total | B25: =SUM(B21:B24) -> 247 | C25: =SUM(C21:C24) -> 1 | D25: =E25/B25 -> 6.2631579 | E25: =SUM(E21:E24) -> 1547 | F25: =SUM(F21:F24) -> 1 | J25: =SUM(J21:J24) -> 52 | L25: =SUM(L21:L24) -> 24
A28: By doctor
A29: Doctor | B29: Admissions | C29: % of admissions | D29: ALOS (days) | E29: Bed-days | F29: % of bed-days | G29: Long-stay rate | H29: High-severity share | I29: Uninsured rate | J29: Genuine bills | K29: Avg genuine bill | L29: Clinical review flags
A30: Dr. Reem Abdullah | B30: =COUNTIFS('Clean Data'!$J$2:$J$248,$A30) -> 42 | C30: =B30/COUNTA('Clean Data'!$A$2:$A$248) -> 0.17004049 | D30: =IFERROR(AVERAGEIFS('Clean Data'!$N$2:$N$248,'Clean Data'!$J$2:$J$248,$A30),"") -> 7.4761905 | E30: =SUMIFS('Clean Data'!$N$2:$N$248,'Clean Data'!$J$2:$J$248,$A30) -> 314 | F30: =E30/SUM('Clean Data'!$N$2:$N$248) -> 0.2029735 | G30: =IFERROR(COUNTIFS('Clean Data'!$J$2:$J$248,$A30,'Clean Data'!$P$2:$P$248,TRUE())/B30,"") -> 0.35714286 | H30: =IFERROR(COUNTIFS('Clean Data'!$J$2:$J$248,$A30,'Clean Data'!$AB$2:$AB$248,TRUE())/B30,"") -> 0.45238095 | I30: =IFERROR(COUNTIFS('Clean Data'!$J$2:$J$248,$A30,'Clean Data'!$Y$2:$Y$248,TRUE())/B30,"") -> 0.35714286 | J30: =COUNTIFS('Clean Data'!$J$2:$J$248,$A30,'Clean Data'!$AC$2:$AC$248,"<>") -> 6 | K30: =IFERROR(AVERAGEIFS('Clean Data'!$AC$2:$AC$248,'Clean Data'!$J$2:$J$248,$A30),"-") -> 4035.5 | L30: =COUNTIFS('Clean Data'!$J$2:$J$248,$A30,'Clean Data'!$AH$2:$AH$248,"?*") -> 3
A31: Dr. Mohamed Hassan | B31: =COUNTIFS('Clean Data'!$J$2:$J$248,$A31) -> 41 | C31: =B31/COUNTA('Clean Data'!$A$2:$A$248) -> 0.1659919 | D31: =IFERROR(AVERAGEIFS('Clean Data'!$N$2:$N$248,'Clean Data'!$J$2:$J$248,$A31),"") -> 7.195122 | E31: =SUMIFS('Clean Data'!$N$2:$N$248,'Clean Data'!$J$2:$J$248,$A31) -> 295 | F31: =E31/SUM('Clean Data'!$N$2:$N$248) -> 0.19069166 | G31: =IFERROR(COUNTIFS('Clean Data'!$J$2:$J$248,$A31,'Clean Data'!$P$2:$P$248,TRUE())/B31,"") -> 0.34146341 | H31: =IFERROR(COUNTIFS('Clean Data'!$J$2:$J$248,$A31,'Clean Data'!$AB$2:$AB$248,TRUE())/B31,"") -> 0.31707317 | I31: =IFERROR(COUNTIFS('Clean Data'!$J$2:$J$248,$A31,'Clean Data'!$Y$2:$Y$248,TRUE())/B31,"") -> 0.31707317 | J31: =COUNTIFS('Clean Data'!$J$2:$J$248,$A31,'Clean Data'!$AC$2:$AC$248,"<>") -> 8 | K31: =IFERROR(AVERAGEIFS('Clean Data'!$AC$2:$AC$248,'Clean Data'!$J$2:$J$248,$A31),"-") -> 2417.5 | L31: =COUNTIFS('Clean Data'!$J$2:$J$248,$A31,'Clean Data'!$AH$2:$AH$248,"?*") -> 9
A32: Dr. Ahmed Ali | B32: =COUNTIFS('Clean Data'!$J$2:$J$248,$A32) -> 40 | C32: =B32/COUNTA('Clean Data'!$A$2:$A$248) -> 0.16194332 | D32: =IFERROR(AVERAGEIFS('Clean Data'!$N$2:$N$248,'Clean Data'!$J$2:$J$248,$A32),"") -> 5.15 | E32: =SUMIFS('Clean Data'!$N$2:$N$248,'Clean Data'!$J$2:$J$248,$A32) -> 206 | F32: =E32/SUM('Clean Data'!$N$2:$N$248) -> 0.13316096 | G32: =IFERROR(COUNTIFS('Clean Data'!$J$2:$J$248,$A32,'Clean Data'!$P$2:$P$248,TRUE())/B32,"") -> 0.2 | H32: =IFERROR(COUNTIFS('Clean Data'!$J$2:$J$248,$A32,'Clean Data'!$AB$2:$AB$248,TRUE())/B32,"") -> 0.325 | I32: =IFERROR(COUNTIFS('Clean Data'!$J$2:$J$248,$A32,'Clean Data'!$Y$2:$Y$248,TRUE())/B32,"") -> 0.275 | J32: =COUNTIFS('Clean Data'!$J$2:$J$248,$A32,'Clean Data'!$AC$2:$AC$248,"<>") -> 13 | K32: =IFERROR(AVERAGEIFS('Clean Data'!$AC$2:$AC$248,'Clean Data'!$J$2:$J$248,$A32),"-") -> 3072.4615 | L32: =COUNTIFS('Clean Data'!$J$2:$J$248,$A32,'Clean Data'!$AH$2:$AH$248,"?*") -> 0
A33: Dr. Yasmin Mahmoud | B33: =COUNTIFS('Clean Data'!$J$2:$J$248,$A33) -> 39 | C33: =B33/COUNTA('Clean Data'!$A$2:$A$248) -> 0.15789474 | D33: =IFERROR(AVERAGEIFS('Clean Data'!$N$2:$N$248,'Clean Data'!$J$2:$J$248,$A33),"") -> 6.9230769 | E33: =SUMIFS('Clean Data'!$N$2:$N$248,'Clean Data'!$J$2:$J$248,$A33) -> 270 | F33: =E33/SUM('Clean Data'!$N$2:$N$248) -> 0.17453135 | G33: =IFERROR(COUNTIFS('Clean Data'!$J$2:$J$248,$A33,'Clean Data'!$P$2:$P$248,TRUE())/B33,"") -> 0.25641026 | H33: =IFERROR(COUNTIFS('Clean Data'!$J$2:$J$248,$A33,'Clean Data'!$AB$2:$AB$248,TRUE())/B33,"") -> 0.35897436 | I33: =IFERROR(COUNTIFS('Clean Data'!$J$2:$J$248,$A33,'Clean Data'!$Y$2:$Y$248,TRUE())/B33,"") -> 0.25641026 | J33: =COUNTIFS('Clean Data'!$J$2:$J$248,$A33,'Clean Data'!$AC$2:$AC$248,"<>") -> 5 | K33: =IFERROR(AVERAGEIFS('Clean Data'!$AC$2:$AC$248,'Clean Data'!$J$2:$J$248,$A33),"-") -> 4170.6 | L33: =COUNTIFS('Clean Data'!$J$2:$J$248,$A33,'Clean Data'!$AH$2:$AH$248,"?*") -> 4
A34: Dr. Khaled Sami | B34: =COUNTIFS('Clean Data'!$J$2:$J$248,$A34) -> 34 | C34: =B34/COUNTA('Clean Data'!$A$2:$A$248) -> 0.13765182 | D34: =IFERROR(AVERAGEIFS('Clean Data'!$N$2:$N$248,'Clean Data'!$J$2:$J$248,$A34),"") -> 5.7941176 | E34: =SUMIFS('Clean Data'!$N$2:$N$248,'Clean Data'!$J$2:$J$248,$A34) -> 197 | F34: =E34/SUM('Clean Data'!$N$2:$N$248) -> 0.12734324 | G34: =IFERROR(COUNTIFS('Clean Data'!$J$2:$J$248,$A34,'Clean Data'!$P$2:$P$248,TRUE())/B34,"") -> 0.20588235 | H34: =IFERROR(COUNTIFS('Clean Data'!$J$2:$J$248,$A34,'Clean Data'!$AB$2:$AB$248,TRUE())/B34,"") -> 0.35294118 | I34: =IFERROR(COUNTIFS('Clean Data'!$J$2:$J$248,$A34,'Clean Data'!$Y$2:$Y$248,TRUE())/B34,"") -> 0.20588235 | J34: =COUNTIFS('Clean Data'!$J$2:$J$248,$A34,'Clean Data'!$AC$2:$AC$248,"<>") -> 7 | K34: =IFERROR(AVERAGEIFS('Clean Data'!$AC$2:$AC$248,'Clean Data'!$J$2:$J$248,$A34),"-") -> 3569.2857 | L34: =COUNTIFS('Clean Data'!$J$2:$J$248,$A34,'Clean Data'!$AH$2:$AH$248,"?*") -> 4
A35: Dr. Nour Khaled | B35: =COUNTIFS('Clean Data'!$J$2:$J$248,$A35) -> 27 | C35: =B35/COUNTA('Clean Data'!$A$2:$A$248) -> 0.10931174 | D35: =IFERROR(AVERAGEIFS('Clean Data'!$N$2:$N$248,'Clean Data'!$J$2:$J$248,$A35),"") -> 5.6296296 | E35: =SUMIFS('Clean Data'!$N$2:$N$248,'Clean Data'!$J$2:$J$248,$A35) -> 152 | F35: =E35/SUM('Clean Data'!$N$2:$N$248) -> 0.098254686 | G35: =IFERROR(COUNTIFS('Clean Data'!$J$2:$J$248,$A35,'Clean Data'!$P$2:$P$248,TRUE())/B35,"") -> 0.18518519 | H35: =IFERROR(COUNTIFS('Clean Data'!$J$2:$J$248,$A35,'Clean Data'!$AB$2:$AB$248,TRUE())/B35,"") -> 0.40740741 | I35: =IFERROR(COUNTIFS('Clean Data'!$J$2:$J$248,$A35,'Clean Data'!$Y$2:$Y$248,TRUE())/B35,"") -> 0.2962963 | J35: =COUNTIFS('Clean Data'!$J$2:$J$248,$A35,'Clean Data'!$AC$2:$AC$248,"<>") -> 8 | K35: =IFERROR(AVERAGEIFS('Clean Data'!$AC$2:$AC$248,'Clean Data'!$J$2:$J$248,$A35),"-") -> 1529.875 | L35: =COUNTIFS('Clean Data'!$J$2:$J$248,$A35,'Clean Data'!$AH$2:$AH$248,"?*") -> 3
A36: Dr. Sara Ibrahim | B36: =COUNTIFS('Clean Data'!$J$2:$J$248,$A36) -> 24 | C36: =B36/COUNTA('Clean Data'!$A$2:$A$248) -> 0.097165992 | D36: =IFERROR(AVERAGEIFS('Clean Data'!$N$2:$N$248,'Clean Data'!$J$2:$J$248,$A36),"") -> 4.7083333 | E36: =SUMIFS('Clean Data'!$N$2:$N$248,'Clean Data'!$J$2:$J$248,$A36) -> 113 | F36: =E36/SUM('Clean Data'!$N$2:$N$248) -> 0.073044602 | G36: =IFERROR(COUNTIFS('Clean Data'!$J$2:$J$248,$A36,'Clean Data'!$P$2:$P$248,TRUE())/B36,"") -> 0.16666667 | H36: =IFERROR(COUNTIFS('Clean Data'!$J$2:$J$248,$A36,'Clean Data'!$AB$2:$AB$248,TRUE())/B36,"") -> 0.29166667 | I36: =IFERROR(COUNTIFS('Clean Data'!$J$2:$J$248,$A36,'Clean Data'!$Y$2:$Y$248,TRUE())/B36,"") -> 0.33333333 | J36: =COUNTIFS('Clean Data'!$J$2:$J$248,$A36,'Clean Data'!$AC$2:$AC$248,"<>") -> 5 | K36: =IFERROR(AVERAGEIFS('Clean Data'!$AC$2:$AC$248,'Clean Data'!$J$2:$J$248,$A36),"-") -> 2316.6 | L36: =COUNTIFS('Clean Data'!$J$2:$J$248,$A36,'Clean Data'!$AH$2:$AH$248,"?*") -> 1
A37: Total | B37: =SUM(B30:B36) -> 247 | C37: =SUM(C30:C36) -> 1 | D37: =E37/B37 -> 6.2631579 | E37: =SUM(E30:E36) -> 1547 | F37: =SUM(F30:F36) -> 1 | J37: =SUM(J30:J36) -> 52 | L37: =SUM(L30:L36) -> 24
A40: By insurance
A41: Insurance | B41: Admissions | C41: % of admissions | D41: ALOS (days) | E41: Bed-days | F41: % of bed-days | G41: Long-stay rate | H41: High-severity share | I41: Uninsured rate | J41: Genuine bills | K41: Avg genuine bill | L41: Clinical review flags
A42: Private | B42: =COUNTIFS('Clean Data'!$W$2:$W$248,$A42) -> 92 | C42: =B42/COUNTA('Clean Data'!$A$2:$A$248) -> 0.37246964 | D42: =IFERROR(AVERAGEIFS('Clean Data'!$N$2:$N$248,'Clean Data'!$W$2:$W$248,$A42),"") -> 6.0869565 | E42: =SUMIFS('Clean Data'!$N$2:$N$248,'Clean Data'!$W$2:$W$248,$A42) -> 560 | F42: =E42/SUM('Clean Data'!$N$2:$N$248) -> 0.36199095 | G42: =IFERROR(COUNTIFS('Clean Data'!$W$2:$W$248,$A42,'Clean Data'!$P$2:$P$248,TRUE())/B42,"") -> 0.2173913 | H42: =IFERROR(COUNTIFS('Clean Data'!$W$2:$W$248,$A42,'Clean Data'!$AB$2:$AB$248,TRUE())/B42,"") -> 0.35869565 | I42: =IFERROR(COUNTIFS('Clean Data'!$W$2:$W$248,$A42,'Clean Data'!$Y$2:$Y$248,TRUE())/B42,"") -> 0 | J42: =COUNTIFS('Clean Data'!$W$2:$W$248,$A42,'Clean Data'!$AC$2:$AC$248,"<>") -> 23 | K42: =IFERROR(AVERAGEIFS('Clean Data'!$AC$2:$AC$248,'Clean Data'!$W$2:$W$248,$A42),"-") -> 3054.4348 | L42: =COUNTIFS('Clean Data'!$W$2:$W$248,$A42,'Clean Data'!$AH$2:$AH$248,"?*") -> 10
A43: Government | B43: =COUNTIFS('Clean Data'!$W$2:$W$248,$A43) -> 83 | C43: =B43/COUNTA('Clean Data'!$A$2:$A$248) -> 0.33603239 | D43: =IFERROR(AVERAGEIFS('Clean Data'!$N$2:$N$248,'Clean Data'!$W$2:$W$248,$A43),"") -> 6.3493976 | E43: =SUMIFS('Clean Data'!$N$2:$N$248,'Clean Data'!$W$2:$W$248,$A43) -> 527 | F43: =E43/SUM('Clean Data'!$N$2:$N$248) -> 0.34065934 | G43: =IFERROR(COUNTIFS('Clean Data'!$W$2:$W$248,$A43,'Clean Data'!$P$2:$P$248,TRUE())/B43,"") -> 0.26506024 | H43: =IFERROR(COUNTIFS('Clean Data'!$W$2:$W$248,$A43,'Clean Data'!$AB$2:$AB$248,TRUE())/B43,"") -> 0.36144578 | I43: =IFERROR(COUNTIFS('Clean Data'!$W$2:$W$248,$A43,'Clean Data'!$Y$2:$Y$248,TRUE())/B43,"") -> 0 | J43: =COUNTIFS('Clean Data'!$W$2:$W$248,$A43,'Clean Data'!$AC$2:$AC$248,"<>") -> 18 | K43: =IFERROR(AVERAGEIFS('Clean Data'!$AC$2:$AC$248,'Clean Data'!$W$2:$W$248,$A43),"-") -> 3184.3333 | L43: =COUNTIFS('Clean Data'!$W$2:$W$248,$A43,'Clean Data'!$AH$2:$AH$248,"?*") -> 10
A44: Uninsured | B44: =COUNTIFS('Clean Data'!$W$2:$W$248,$A44) -> 72 | C44: =B44/COUNTA('Clean Data'!$A$2:$A$248) -> 0.29149798 | D44: =IFERROR(AVERAGEIFS('Clean Data'!$N$2:$N$248,'Clean Data'!$W$2:$W$248,$A44),"") -> 6.3888889 | E44: =SUMIFS('Clean Data'!$N$2:$N$248,'Clean Data'!$W$2:$W$248,$A44) -> 460 | F44: =E44/SUM('Clean Data'!$N$2:$N$248) -> 0.29734971 | G44: =IFERROR(COUNTIFS('Clean Data'!$W$2:$W$248,$A44,'Clean Data'!$P$2:$P$248,TRUE())/B44,"") -> 0.29166667 | H44: =IFERROR(COUNTIFS('Clean Data'!$W$2:$W$248,$A44,'Clean Data'!$AB$2:$AB$248,TRUE())/B44,"") -> 0.36111111 | I44: =IFERROR(COUNTIFS('Clean Data'!$W$2:$W$248,$A44,'Clean Data'!$Y$2:$Y$248,TRUE())/B44,"") -> 1 | J44: =COUNTIFS('Clean Data'!$W$2:$W$248,$A44,'Clean Data'!$AC$2:$AC$248,"<>") -> 11 | K44: =IFERROR(AVERAGEIFS('Clean Data'!$AC$2:$AC$248,'Clean Data'!$W$2:$W$248,$A44),"-") -> 2325.9091 | L44: =COUNTIFS('Clean Data'!$W$2:$W$248,$A44,'Clean Data'!$AH$2:$AH$248,"?*") -> 4
A45: Total | B45: =SUM(B42:B44) -> 247 | C45: =SUM(C42:C44) -> 1 | D45: =E45/B45 -> 6.2631579 | E45: =SUM(E42:E44) -> 1547 | F45: =SUM(F42:F44) -> 1 | J45: =SUM(J42:J44) -> 52 | L45: =SUM(L42:L44) -> 24
A48: By severity
A49: Severity | B49: Admissions | C49: % of admissions | D49: ALOS (days) | E49: Bed-days | F49: % of bed-days | G49: Long-stay rate | H49: High-severity share | I49: Uninsured rate | J49: Genuine bills | K49: Avg genuine bill | L49: Clinical review flags
...

Sheet Severity x Dx
A1: Severity mix by diagnosis
A2: Row % of each diagnosis by recorded severity. Watch for mismatches: stroke mostly 'Low', common cold mostly 'High'.
A4: Diagnosis | B4: Low (n) | C4: Medium (n) | D4: High (n) | E4: Total | F4: Low % | G4: Medium % | H4: High % | I4: ALOS (days)
A5: Influenza | B5: =COUNTIFS('Clean Data'!$G$2:$G$248,$A5,'Clean Data'!$Z$2:$Z$248,"Low") -> 12 | C5: =COUNTIFS('Clean Data'!$G$2:$G$248,$A5,'Clean Data'!$Z$2:$Z$248,"Medium") -> 15 | D5: =COUNTIFS('Clean Data'!$G$2:$G$248,$A5,'Clean Data'!$Z$2:$Z$248,"High") -> 13 | E5: =SUM(B5:D5) -> 40 | F5: =B5/$E5 -> 0.3 | G5: =C5/$E5 -> 0.375 | H5: =D5/$E5 -> 0.325 | I5: =AVERAGEIFS('Clean Data'!$N$2:$N$248,'Clean Data'!$G$2:$G$248,$A5) -> 6.275
A6: Fractures | B6: =COUNTIFS('Clean Data'!$G$2:$G$248,$A6,'Clean Data'!$Z$2:$Z$248,"Low") -> 15 | C6: =COUNTIFS('Clean Data'!$G$2:$G$248,$A6,'Clean Data'!$Z$2:$Z$248,"Medium") -> 12 | D6: =COUNTIFS('Clean Data'!$G$2:$G$248,$A6,'Clean Data'!$Z$2:$Z$248,"High") -> 10 | E6: =SUM(B6:D6) -> 37 | F6: =B6/$E6 -> 0.40540541 | G6: =C6/$E6 -> 0.32432432 | H6: =D6/$E6 -> 0.27027027 | I6: =AVERAGEIFS('Clean Data'!$N$2:$N$248,'Clean Data'!$G$2:$G$248,$A6) -> 5.1351351
A7: Chronic Allergy | B7: =COUNTIFS('Clean Data'!$G$2:$G$248,$A7,'Clean Data'!$Z$2:$Z$248,"Low") -> 8 | C7: =COUNTIFS('Clean Data'!$G$2:$G$248,$A7,'Clean Data'!$Z$2:$Z$248,"Medium") -> 10 | D7: =COUNTIFS('Clean Data'!$G$2:$G$248,$A7,'Clean Data'!$Z$2:$Z$248,"High") -> 16 | E7: =SUM(B7:D7) -> 34 | F7: =B7/$E7 -> 0.23529412 | G7: =C7/$E7 -> 0.29411765 | H7: =D7/$E7 -> 0.47058824 | I7: =AVERAGEIFS('Clean Data'!$N$2:$N$248,'Clean Data'!$G$2:$G$248,$A7) -> 6.7941176
A8: Common Cold | B8: =COUNTIFS('Clean Data'!$G$2:$G$248,$A8,'Clean Data'!$Z$2:$Z$248,"Low") -> 11 | C8: =COUNTIFS('Clean Data'!$G$2:$G$248,$A8,'Clean Data'!$Z$2:$Z$248,"Medium") -> 5 | D8: =COUNTIFS('Clean Data'!$G$2:$G$248,$A8,'Clean Data'!$Z$2:$Z$248,"High") -> 15 | E8: =SUM(B8:D8) -> 31 | F8: =B8/$E8 -> 0.35483871 | G8: =C8/$E8 -> 0.16129032 | H8: =D8/$E8 -> 0.48387097 | I8: =AVERAGEIFS('Clean Data'!$N$2:$N$248,'Clean Data'!$G$2:$G$248,$A8) -> 7.7419355
A9: Diabetes | B9: =COUNTIFS('Clean Data'!$G$2:$G$248,$A9,'Clean Data'!$Z$2:$Z$248,"Low") -> 4 | C9: =COUNTIFS('Clean Data'!$G$2:$G$248,$A9,'Clean Data'!$Z$2:$Z$248,"Medium") -> 11 | D9: =COUNTIFS('Clean Data'!$G$2:$G$248,$A9,'Clean Data'!$Z$2:$Z$248,"High") -> 13 | E9: =SUM(B9:D9) -> 28 | F9: =B9/$E9 -> 0.14285714 | G9: =C9/$E9 -> 0.39285714 | H9: =D9/$E9 -> 0.46428571 | I9: =AVERAGEIFS('Clean Data'!$N$2:$N$248,'Clean Data'!$G$2:$G$248,$A9) -> 5.6428571
A10: Hypertension | B10: =COUNTIFS('Clean Data'!$G$2:$G$248,$A10,'Clean Data'!$Z$2:$Z$248,"Low") -> 13 | C10: =COUNTIFS('Clean Data'!$G$2:$G$248,$A10,'Clean Data'!$Z$2:$Z$248,"Medium") -> 6 | D10: =COUNTIFS('Clean Data'!$G$2:$G$248,$A10,'Clean Data'!$Z$2:$Z$248,"High") -> 5 | E10: =SUM(B10:D10) -> 24 | F10: =B10/$E10 -> 0.54166667 | G10: =C10/$E10 -> 0.25 | H10: =D10/$E10 -> 0.20833333 | I10: =AVERAGEIFS('Clean Data'!$N$2:$N$248,'Clean Data'!$G$2:$G$248,$A10) -> 5.7916667
A11: Kidney Failure | B11: =COUNTIFS('Clean Data'!$G$2:$G$248,$A11,'Clean Data'!$Z$2:$Z$248,"Low") -> 4 | C11: =COUNTIFS('Clean Data'!$G$2:$G$248,$A11,'Clean Data'!$Z$2:$Z$248,"Medium") -> 10 | D11: =COUNTIFS('Clean Data'!$G$2:$G$248,$A11,'Clean Data'!$Z$2:$Z$248,"High") -> 5 | E11: =SUM(B11:D11) -> 19 | F11: =B11/$E11 -> 0.21052632 | G11: =C11/$E11 -> 0.52631579 | H11: =D11/$E11 -> 0.26315789 | I11: =AVERAGEIFS('Clean Data'!$N$2:$N$248,'Clean Data'!$G$2:$G$248,$A11) -> 6.4210526
A12: Migraine | B12: =COUNTIFS('Clean Data'!$G$2:$G$248,$A12,'Clean Data'!$Z$2:$Z$248,"Low") -> 8 | C12: =COUNTIFS('Clean Data'!$G$2:$G$248,$A12,'Clean Data'!$Z$2:$Z$248,"Medium") -> 4 | D12: =COUNTIFS('Clean Data'!$G$2:$G$248,$A12,'Clean Data'!$Z$2:$Z$248,"High") -> 3 | E12: =SUM(B12:D12) -> 15 | F12: =B12/$E12 -> 0.53333333 | G12: =C12/$E12 -> 0.26666667 | H12: =D12/$E12 -> 0.2 | I12: =AVERAGEIFS('Clean Data'!$N$2:$N$248,'Clean Data'!$G$2:$G$248,$A12) -> 6.4
A13: Stroke | B13: =COUNTIFS('Clean Data'!$G$2:$G$248,$A13,'Clean Data'!$Z$2:$Z$248,"Low") -> 5 | C13: =COUNTIFS('Clean Data'!$G$2:$G$248,$A13,'Clean Data'!$Z$2:$Z$248,"Medium") -> 3 | D13: =COUNTIFS('Clean Data'!$G$2:$G$248,$A13,'Clean Data'!$Z$2:$Z$248,"High") -> 3 | E13: =SUM(B13:D13) -> 11 | F13: =B13/$E13 -> 0.45454545 | G13: =C13/$E13 -> 0.27272727 | H13: =D13/$E13 -> 0.27272727 | I13: =AVERAGEIFS('Clean Data'!$N$2:$N$248,'Clean Data'!$G$2:$G$248,$A13) -> 7.4545455
A14: Pneumonia | B14: =COUNTIFS('Clean Data'!$G$2:$G$248,$A14,'Clean Data'!$Z$2:$Z$248,"Low") -> 1 | C14: =COUNTIFS('Clean Data'!$G$2:$G$248,$A14,'Clean Data'!$Z$2:$Z$248,"Medium") -> 1 | D14: =COUNTIFS('Clean Data'!$G$2:$G$248,$A14,'Clean Data'!$Z$2:$Z$248,"High") -> 6 | E14: =SUM(B14:D14) -> 8 | F14: =B14/$E14 -> 0.125 | G14: =C14/$E14 -> 0.125 | H14: =D14/$E14 -> 0.75 | I14: =AVERAGEIFS('Clean Data'!$N$2:$N$248,'Clean Data'!$G$2:$G$248,$A14) -> 4.75

Sheet Clean Data
A1: Patient_ID | B1: Patient_Name | C1: Age | D1: Age_Group | E1: Gender | F1: Gender_AR | G1: Diagnosis | H1: Diagnosis_AR | I1: Diagnosis_Group | J1: Doctor | K1: Doctor_AR | L1: Admission_Date | M1: Discharge_Date | N1: Length_of_Stay | O1: Stay_Band | P1: Long_Stay | Q1: LOS_Outlier | R1: Admission_Month | S1: Admission_Month_Name | T1: Admission_Quarter | U1: Admission_Weekday | V1: Is_Weekend | W1: Insurance | X1: Insurance_AR | Y1: Is_Uninsured | Z1: Severity | AA1: Severity_AR | AB1: High_Severity | AC1: Bill | AD1: Bill_Raw | AE1: Bill_Status | AF1: Bill_Per_Day | AG1: Date_Corrected | AH1: Review_Flag
A2: P0001 | B2: ندى حسن | C2: 42 | D2: Middle age (40-59) | E2: Female | F2: أنثى | G2: Kidney Failure | H2: فشل كلوي | I2: Chronic disease | J2: Dr. Reem Abdullah | K2: د. ريم عبد الله | L2: 45112 | M2: 45129 | N2: 17 | O2: 15+ days | P2: =TRUE() -> TRUE | Q2: =FALSE() -> FALSE | R2: 7 | S2: Jul | T2: Q3 | U2: Wednesday | V2: =FALSE() -> FALSE | W2: Uninsured | X2: بدون تأمين | Y2: =TRUE() -> TRUE | Z2: High | AA2: مرتفع | AB2: =TRUE() -> TRUE | AD2: 3852 | AE2: Placeholder 3852 | AG2: =FALSE() -> FALSE
A3: P0002 | B3: ياسمين محمود | C3: 33 | D3: Adult (18-39) | E3: Male | F3: ذكر | G3: Kidney Failure | H3: فشل كلوي | I3: Chronic disease | J3: Dr. Reem Abdullah | K3: د. ريم عبد الله | L3: 44990 | M3: 44993 | N3: 3 | O3: 1-3 days | P3: =FALSE() -> FALSE | Q3: =FALSE() -> FALSE | R3: 3 | S3: Mar | T3: Q1 | U3: Sunday | V3: =FALSE() -> FALSE | W3: Private | X3: تأمين خاص | Y3: =FALSE() -> FALSE | Z3: Medium | AA3: متوسط | AB3: =FALSE() -> FALSE | AD3: 3852 | AE3: Placeholder 3852 | AG3: =FALSE() -> FALSE
A4: P0003 | B4: يوسف عبد الله | C4: 42 | D4: Middle age (40-59) | E4: Female | F4: أنثى | G4: Influenza | H4: أنفلونزا | I4: Respiratory infection | J4: Dr. Sara Ibrahim | K4: د. سارة إبراهيم | L4: 45225 | M4: 45226 | N4: 1 | O4: 1-3 days | P4: =FALSE() -> FALSE | Q4: =FALSE() -> FALSE | R4: 10 | S4: Oct | T4: Q4 | U4: Thursday | V4: =FALSE() -> FALSE | W4: Uninsured | X4: بدون تأمين | Y4: =TRUE() -> TRUE | Z4: High | AA4: مرتفع | AB4: =TRUE() -> TRUE | AC4: 961 | AD4: 961 | AE4: Recorded | AF4: 961 | AG4: =FALSE() -> FALSE
A5: P0004 | B5: ياسمين عبد الله | C5: 84 | D5: Senior (60+) | E5: Male | F5: ذكر | G5: Influenza | H5: أنفلونزا | I5: Respiratory infection | J5: Dr. Ahmed Ali | K5: د. أحمد علي | L5: 45087 | M5: 45089 | N5: 2 | O5: 1-3 days | P5: =FALSE() -> FALSE | Q5: =FALSE() -> FALSE | R5: 6 | S5: Jun | T5: Q2 | U5: Saturday | V5: =TRUE() -> TRUE | W5: Private | X5: تأمين خاص | Y5: =FALSE() -> FALSE | Z5: High | AA5: مرتفع | AB5: =TRUE() -> TRUE | AC5: 1165 | AD5: 1165 | AE5: Recorded | AF5: 582.5 | AG5: =FALSE() -> FALSE
A6: P0005 | B6: مريم عبد الله | C6: 58 | D6: Middle age (40-59) | E6: Female | F6: أنثى | G6: Influenza | H6: أنفلونزا | I6: Respiratory infection | J6: Dr. Khaled Sami | K6: د. خالد سامي | L6: 45084 | M6: 45088 | N6: 4 | O6: 4-7 days | P6: =FALSE() -> FALSE | Q6: =FALSE() -> FALSE | R6: 6 | S6: Jun | T6: Q2 | U6: Wednesday | V6: =FALSE() -> FALSE | W6: Government | X6: تأمين حكومي | Y6: =FALSE() -> FALSE | Z6: High | AA6: مرتفع | AB6: =TRUE() -> TRUE | AD6: 3852 | AE6: Placeholder 3852 | AG6: =FALSE() -> FALSE
A7: P0006 | B7: يوسف محمود | C7: 17 | D7: Child (0-17) | E7: Female | F7: أنثى | G7: Influenza | H7: أنفلونزا | I7: Respiratory infection | J7: Dr. Reem Abdullah | K7: د. ريم عبد الله | L7: 44962 | M7: 44971 | N7: 9 | O7: 8-14 days | P7: =TRUE() -> TRUE | Q7: =FALSE() -> FALSE | R7: 2 | S7: Feb | T7: Q1 | U7: Sunday | V7: =FALSE() -> FALSE | W7: Government | X7: تأمين حكومي | Y7: =FALSE() -> FALSE | Z7: Medium | AA7: متوسط | AB7: =FALSE() -> FALSE | AD7: 3852 | AE7: Placeholder 3852 | AG7: =FALSE() -> FALSE
A8: P0007 | B8: علي يوسف | C8: 85 | D8: Senior (60+) | E8: Male | F8: ذكر | G8: Influenza | H8: أنفلونزا | I8: Respiratory infection | J8: Dr. Nour Khaled | K8: د. نور خالد | L8: 45285 | M8: 45287 | N8: 2 | O8: 1-3 days | P8: =FALSE() -> FALSE | Q8: =FALSE() -> FALSE | R8: 12 | S8: Dec | T8: Q4 | U8: Monday | V8: =FALSE() -> FALSE | W8: Private | X8: تأمين خاص | Y8: =FALSE() -> FALSE | Z8: Low | AA8: منخفض | AB8: =FALSE() -> FALSE | AD8: 999 | AE8: Placeholder 999 | AG8: =FALSE() -> FALSE
A9: P0008 | B9: إبراهيم يوسف | C9: 42 | D9: Middle age (40-59) | E9: Male | F9: ذكر | G9: Influenza | H9: أنفلونزا | I9: Respiratory infection | J9: Dr. Mohamed Hassan | K9: د. محمد حسن | L9: 45051 | M9: 45054 | N9: 3 | O9: 1-3 days | P9: =FALSE() -> FALSE | Q9: =FALSE() -> FALSE | R9: 5 | S9: May | T9: Q2 | U9: Friday | V9: =TRUE() -> TRUE | W9: Government | X9: تأمين حكومي | Y9: =FALSE() -> FALSE | Z9: High | AA9: مرتفع | AB9: =TRUE() -> TRUE | AD9: 999 | AE9: Placeholder 999 | AG9: =FALSE() -> FALSE
A10: P0009 | B10: علي حسن | C10: 18 | D10: Adult (18-39) | E10: Female | F10: أنثى | G10: Influenza | H10: أنفلونزا | I10: Respiratory infection | J10: Dr. Yasmin Mahmoud | K10: د. ياسمين محمود | L10: 45217 | M10: 45219 | N10: 2 | O10: 1-3 days | P10: =FALSE() -> FALSE | Q10: =FALSE() -> FALSE | R10: 10 | S10: Oct | T10: Q4 | U10: Wednesday | V10: =FALSE() -> FALSE | W10: Private | X10: تأمين خاص | Y10: =FALSE() -> FALSE | Z10: High | AA10: مرتفع | AB10: =TRUE() -> TRUE | AD10: 3852 | AE10: Placeholder 3852 | AG10: =FALSE() -> FALSE
A11: P0010 | B11: إبراهيم يوسف | C11: 40 | D11: Middle age (40-59) | E11: Female | F11: أنثى | G11: Influenza | H11: أنفلونزا | I11: Respiratory infection | J11: Dr. Sara Ibrahim | K11: د. سارة إبراهيم | L11: 45112 | M11: 45113 | N11: 1 | O11: 1-3 days | P11: =FALSE() -> FALSE | Q11: =FALSE() -> FALSE | R11: 7 | S11: Jul | T11: Q3 | U11: Wednesday | V11: =FALSE() -> FALSE | W11: Private | X11: تأمين خاص | Y11: =FALSE() -> FALSE | Z11: Low | AA11: منخفض | AB11: =FALSE() -> FALSE | AD11: 999 | AE11: Placeholder 999 | AG11: =FALSE() -> FALSE
A12: P0011 | B12: مريم السيد | C12: 78 | D12: Senior (60+) | E12: Male | F12: ذكر | G12: Influenza | H12: أنفلونزا | I12: Respiratory infection | J12: Dr. Ahmed Ali | K12: د. أحمد علي | L12: 45253 | M12: 45267 | N12: 14 | O12: 8-14 days | P12: =TRUE() -> TRUE | Q12: =FALSE() -> FALSE | R12: 11 | S12: Nov | T12: Q4 | U12: Thursday | V12: =FALSE() -> FALSE | W12: Government | X12: تأمين حكومي | Y12: =FALSE() -> FALSE | Z12: Medium | AA12: متوسط | AB12: =FALSE() -> FALSE | AD12: 999 | AE12: Placeholder 999 | AG12: =FALSE() -> FALSE
A13: P0012 | B13: محمود خالد | C13: 11 | D13: Child (0-17) | E13: Male | F13: ذكر | G13: Influenza | H13: أنفلونزا | I13: Respiratory infection | J13: Dr. Mohamed Hassan | K13: د. محمد حسن | L13: 44948 | M13: 44961 | N13: 13 | O13: 8-14 days | P13: =TRUE() -> TRUE | Q13: =FALSE() -> FALSE | R13: 1 | S13: Jan | T13: Q1 | U13: Sunday | V13: =FALSE() -> FALSE | W13: Uninsured | X13: بدون تأمين | Y13: =TRUE() -> TRUE | Z13: High | AA13: مرتفع | AB13: =TRUE() -> TRUE | AD13: 3852 | AE13: Placeholder 3852 | AG13: =FALSE() -> FALSE
A14: P0013 | B14: أحمد علي | C14: 50 | D14: Middle age (40-59) | E14: Female | F14: أنثى | G14: Influenza | H14: أنفلونزا | I14: Respiratory infection | J14: Dr. Reem Abdullah | K14: د. ريم عبد الله | L14: 45253 | M14: 45257 | N14: 4 | O14: 4-7 days | P14: =FALSE() -> FALSE | Q14: =FALSE() -> FALSE | R14: 11 | S14: Nov | T14: Q4 | U14: Thursday | V14: =FALSE() -> FALSE | W14: Private | X14: تأمين خاص | Y14: =FALSE() -> FALSE | Z14: Medium | AA14: متوسط | AB14: =FALSE() -> FALSE | AC14: 3898 | AD14: 3898 | AE14: Recorded | AF14: 974.5 | AG14: =FALSE() -> FALSE
A15: P0014 | B15: ياسمين السيد | C15: 87 | D15: Senior (60+) | E15: Male | F15: ذكر | G15: Influenza | H15: أنفلونزا | I15: Respiratory infection | J15: Dr. Nour Khaled | K15: د. نور خالد | L15: 45051 | M15: 45063 | N15: 12 | O15: 8-14 days | P15: =TRUE() -> TRUE | Q15: =FALSE() -> FALSE | R15: 5 | S15: May | T15: Q2 | U15: Friday | V15: =TRUE() -> TRUE | W15: Uninsured | X15: بدون تأمين | Y15: =TRUE() -> TRUE | Z15: Medium | AA15: متوسط | AB15: =FALSE() -> FALSE | AD15: 3852 | AE15: Placeholder 3852 | AG15: =FALSE() -> FALSE
A16: P0015 | B16: علي محمود | C16: 69 | D16: Senior (60+) | E16: Male | F16: ذكر | G16: Chronic Allergy | H16: حساسية مزمنة | I16: Chronic disease | J16: Dr. Khaled Sami | K16: د. خالد سامي | L16: 44979 | M16: 44982 | N16: 3 | O16: 1-3 days | P16: =FALSE() -> FALSE | Q16: =FALSE() -> FALSE | R16: 2 | S16: Feb | T16: Q1 | U16: Wednesday | V16: =FALSE() -> FALSE | W16: Private | X16: تأمين خاص | Y16: =FALSE() -> FALSE | Z16: Medium | AA16: متوسط | AB16: =FALSE() -> FALSE | AC16: 2390 | AD16: 2390 | AE16: Recorded | AF16: 796.67 | AG16: =FALSE() -> FALSE
A17: P0016 | B17: محمود محمود | C17: 80 | D17: Senior (60+) | E17: Male | F17: ذكر | G17: Chronic Allergy | H17: حساسية مزمنة | I17: Chronic disease | J17: Dr. Reem Abdullah | K17: د. ريم عبد الله | L17: 45105 | M17: 45114 | N17: 9 | O17: 8-14 days | P17: =TRUE() -> TRUE | Q17: =FALSE() -> FALSE | R17: 6 | S17: Jun | T17: Q2 | U17: Wednesday | V17: =FALSE() -> FALSE | W17: Private | X17: تأمين خاص | Y17: =FALSE() -> FALSE | Z17: High | AA17: مرتفع | AB17: =TRUE() -> TRUE | AD17: 999 | AE17: Placeholder 999 | AG17: =FALSE() -> FALSE
A18: P0017 | B18: مريم السيد | C18: 21 | D18: Adult (18-39) | E18: Female | F18: أنثى | G18: Influenza | H18: أنفلونزا | I18: Respiratory infection | J18: Dr. Ahmed Ali | K18: د. أحمد علي | L18: 45089 | M18: 45090 | N18: 1 | O18: 1-3 days | P18: =FALSE() -> FALSE | Q18: =FALSE() -> FALSE | R18: 6 | S18: Jun | T18: Q2 | U18: Monday | V18: =FALSE() -> FALSE | W18: Uninsured | X18: بدون تأمين | Y18: =TRUE() -> TRUE | Z18: Medium | AA18: متوسط | AB18: =FALSE() -> FALSE | AD18: 999 | AE18: Placeholder 999 | AG18: =FALSE() -> FALSE
A19: P0018 | B19: مريم يوسف | C19: 7 | D19: Child (0-17) | E19: Male | F19: ذكر | G19: Influenza | H19: أنفلونزا | I19: Respiratory infection | J19: Dr. Ahmed Ali | K19: د. أحمد علي | L19: 45069 | M19: 45072 | N19: 3 | O19: 1-3 days | P19: =FALSE() -> FALSE | Q19: =FALSE() -> FALSE | R19: 5 | S19: May | T19: Q2 | U19: Tuesday | V19: =FALSE() -> FALSE | W19: Private | X19: تأمين خاص | Y19: =FALSE() -> FALSE | Z19: Low | AA19: منخفض | AB19: =FALSE() -> FALSE | AC19: 973 | AD19: 973 | AE19: Recorded | AF19: 324.33 | AG19: =FALSE() -> FALSE
A20: P0019 | B20: علي السيد | C20: 45 | D20: Middle age (40-59) | E20: Male | F20: ذكر | G20: Influenza | H20: أنفلونزا | I20: Respiratory infection | J20: Dr. Mohamed Hassan | K20: د. محمد حسن | L20: 45235 | M20: 45252 | N20: 17 | O20: 15+ days | P20: =TRUE() -> TRUE | Q20: =FALSE() -> FALSE | R20: 11 | S20: Nov | T20: Q4 | U20: Sunday | V20: =FALSE() -> FALSE | W20: Private | X20: تأمين خاص | Y20: =FALSE() -> FALSE | Z20: Low | AA20: منخفض | AB20: =FALSE() -> FALSE | AD20: 999 | AE20: Placeholder 999 | AG20: =FALSE() -> FALSE | AH20: Long stay for minor condition
A21: P0020 | B21: علي خالد | C21: 21 | D21: Adult (18-39) | E21: Female | F21: أنثى | G21: Influenza | H21: أنفلونزا | I21: Respiratory infection | J21: Dr. Khaled Sami | K21: د. خالد سامي | L21: 45140 | M21: 45144 | N21: 4 | O21: 4-7 days | P21: =FALSE() -> FALSE | Q21: =FALSE() -> FALSE | R21: 8 | S21: Aug | T21: Q3 | U21: Wednesday | V21: =FALSE() -> FALSE | W21: Private | X21: تأمين خاص | Y21: =FALSE() -> FALSE | Z21: High | AA21: مرتفع | AB21: =TRUE() -> TRUE | AD21: 999 | AE21: Placeholder 999 | AG21: =FALSE() -> FALSE
A22: P0021 | B22: محمود يوسف | C22: 72 | D22: Senior (60+) | E22: Female | F22: أنثى | G22: Influenza | H22: أنفلونزا | I22: Respiratory infection | J22: Dr. Sara Ibrahim | K22: د. سارة إبراهيم | L22: 45088 | M22: 45092 | N22: 4 | O22: 4-7 days | P22: =FALSE() -> FALSE | Q22: =FALSE() -> FALSE | R22: 6 | S22: Jun | T22: Q2 | U22: Sunday | V22: =FALSE() -> FALSE | W22: Uninsured | X22: بدون تأمين | Y22: =TRUE() -> TRUE | Z22: Low | AA22: منخفض | AB22: =FALSE() -> FALSE | AC22: 1665 | AD22: 1665 | AE22: Recorded | AF22: 416.25 | AG22: =FALSE() -> FALSE
A23: P0022 | B23: يوسف السيد | C23: 82 | D23: Senior (60+) | E23: Female | F23: أنثى | G23: Influenza | H23: أنفلونزا | I23: Respiratory infection | J23: Dr. Yasmin Mahmoud | K23: د. ياسمين محمود | L23: 45055 | M23: 45069 | N23: 14 | O23: 8-14 days | P23: =TRUE() -> TRUE | Q23: =FALSE() -> FALSE | R23: 5 | S23: May | T23: Q2 | U23: Tuesday | V23: =FALSE() -> FALSE | W23: Private | X23: تأمين خاص | Y23: =FALSE() -> FALSE | Z23: Low | AA23: منخفض | AB23: =FALSE() -> FALSE | AD23: 3852 | AE23: Placeholder 3852 | AG23: =FALSE() -> FALSE
A24: P0023 | B24: محمد يوسف | C24: 67 | D24: Senior (60+) | E24: Female | F24: أنثى | G24: Influenza | H24: أنفلونزا | I24: Respiratory infection | J24: Dr. Reem Abdullah | K24: د. ريم عبد الله | L24: 45111 | M24: 45117 | N24: 6 | O24: 4-7 days | P24: =FALSE() -> FALSE | Q24: =FALSE() -> FALSE | R24: 7 | S24: Jul | T24: Q3 | U24: Tuesday | V24: =FALSE() -> FALSE | W24: Government | X24: تأمين حكومي | Y24: =FALSE() -> FALSE | Z24: Low | AA24: منخفض | AB24: =FALSE() -> FALSE | AD24: 3852 | AE24: Placeholder 3852 | AG24: =FALSE() -> FALSE
A25: P0024 | B25: محمود عبد الله | C25: 44 | D25: Middle age (40-59) | E25: Female | F25: أنثى | G25: Influenza | H25: أنفلونزا | I25: Respiratory infection | J25: Dr. Reem Abdullah | K25: د. ريم عبد الله | L25: 45244 | M25: 45245 | N25: 1 | O25: 1-3 days | P25: =FALSE() -> FALSE | Q25: =FALSE() -> FALSE | R25: 11 | S25: Nov | T25: Q4 | U25: Tuesday | V25: =FALSE() -> FALSE | W25: Private | X25: تأمين خاص | Y25: =FALSE() -> FALSE | Z25: Low | AA25: منخفض | AB25: =FALSE() -> FALSE | AD25: 3852 | AE25: Placeholder 3852 | AG25: =FALSE() -> FALSE
A26: P0025 | B26: ياسمين السيد | C26: 31 | D26: Adult (18-39) | E26: Female | F26: أنثى | G26: Influenza | H26: أنفلونزا | I26: Respiratory infection | J26: Dr. Ahmed Ali | K26: د. أحمد علي | L26: 45018 | M26: 45029 | N26: 11 | O26: 8-14 days | P26: =TRUE() -> TRUE | Q26: =FALSE() -> FALSE | R26: 4 | S26: Apr | T26: Q2 | U26: Sunday | V26: =FALSE() -> FALSE | W26: Government | X26: تأمين حكومي | Y26: =FALSE() -> FALSE | Z26: Medium | AA26: متوسط | AB26: =FALSE() -> FALSE | AD26: 3852 | AE26: Placeholder 3852 | AG26: =FALSE() -> FALSE
A27: P0026 | B27: سارة خالد | C27: 14 | D27: Child (0-17) | E27: Female | F27: أنثى | G27: Influenza | H27: أنفلونزا | I27: Respiratory infection | J27: Dr. Reem Abdullah | K27: د. ريم عبد الله | L27: 45050 | M27: 45054 | N27: 4 | O27: 4-7 days | P27: =FALSE() -> FALSE | Q27: =FALSE() -> FALSE | R27: 5 | S27: May | T27: Q2 | U27: Thursday | V27: =FALSE() -> FALSE | W27: Private | X27: تأمين خاص | Y27: =FALSE() -> FALSE | Z27: Medium | AA27: متوسط | AB27: =FALSE() -> FALSE | AC27: 2973 | AD27: 2973 | AE27: Recorded | AF27: 743.25 | AG27: =FALSE() -> FALSE
A28: P0027 | B28: ياسمين علي | C28: 12 | D28: Child (0-17) | E28: Male | F28: ذكر | G28: Influenza | H28: أنفلونزا | I28: Respiratory infection | J28: Dr. Nour Khaled | K28: د. نور خالد | L28: 44953 | M28: 44969 | N28: 16 | O28: 15+ days | P28: =TRUE() -> TRUE | Q28: =FALSE() -> FALSE | R28: 1 | S28: Jan | T28: Q1 | U28: Friday | V28: =TRUE() -> TRUE | W28: Private | X28: تأمين خاص | Y28: =FALSE() -> FALSE | Z28: Medium | AA28: متوسط | AB28: =FALSE() -> FALSE | AD28: 3852 | AE28: Placeholder 3852 | AG28: =FALSE() -> FALSE | AH28: Long stay for minor condition
A29: P0028 | B29: إبراهيم خالد | C29: 58 | D29: Middle age (40-59) | E29: Male | F29: ذكر | G29: Influenza | H29: أنفلونزا | I29: Respiratory infection | J29: Dr. Yasmin Mahmoud | K29: د. ياسمين محمود | L29: 45011 | M29: 45018 | N29: 7 | O29: 4-7 days | P29: =FALSE() -> FALSE | Q29: =FALSE() -> FALSE | R29: 3 | S29: Mar | T29: Q1 | U29: Sunday | V29: =FALSE() -> FALSE | W29: Uninsured | X29: بدون تأمين | Y29: =TRUE() -> TRUE | Z29: Medium | AA29: متوسط | AB29: =FALSE() -> FALSE | AD29: 999 | AE29: Placeholder 999 | AG29: =FALSE() -> FALSE
A30: P0029 | B30: ياسمين محمود | C30: 36 | D30: Adult (18-39) | E30: Female | F30: أنثى | G30: Influenza | H30: أنفلونزا | I30: Respiratory infection | J30: Dr. Yasmin Mahmoud | K30: د. ياسمين محمود | L30: 45208 | M30: 45222 | N30: 14 | O30: 8-14 days | P30: =TRUE() -> TRUE | Q30: =FALSE() -> FALSE | R30: 10 | S30: Oct | T30: Q4 | U30: Monday | V30: =FALSE() -> FALSE | W30: Private | X30: تأمين خاص | Y30: =FALSE() -> FALSE | Z30: Medium | AA30: متوسط | AB30: =FALSE() -> FALSE | AD30: 999 | AE30: Placeholder 999 | AG30: =FALSE() -> FALSE
A31: P0030 | B31: ندى إبراهيم | C31: 73 | D31: Senior (60+) | E31: Male | F31: ذكر | G31: Influenza | H31: أنفلونزا | I31: Respiratory infection | J31: Dr. Sara Ibrahim | K31: د. سارة إبراهيم | L31: 45209 | M31: 45211 | N31: 2 | O31: 1-3 days | P31: =FALSE() -> FALSE | Q31: =FALSE() -> FALSE | R31: 10 | S31: Oct | T31: Q4 | U31: Tuesday | V31: =FALSE() -> FALSE | W31: Private | X31: تأمين خاص | Y31: =FALSE() -> FALSE | Z31: Low | AA31: منخفض | AB31: =FALSE() -> FALSE | AD31: 3852 | AE31: Placeholder 3852 | AG31: =FALSE() -> FALSE
A32: P0031 | B32: ياسمين عبد الله | C32: 17 | D32: Child (0-17) | E32: Female | F32: أنثى | G32: Influenza | H32: أنفلونزا | I32: Respiratory infection | J32: Dr. Yasmin Mahmoud | K32: د. ياسمين محمود | L32: 45272 | M32: 45273 | N32: 1 | O32: 1-3 days | P32: =FALSE() -> FALSE | Q32: =FALSE() -> FALSE | R32: 12 | S32: Dec | T32: Q4 | U32: Tuesday | V32: =FALSE() -> FALSE | W32: Government | X32: تأمين حكومي | Y32: =FALSE() -> FALSE | Z32: Medium | AA32: متوسط | AB32: =FALSE() -> FALSE | AD32: 3852 | AE32: Placeholder 3852 | AG32: =FALSE() -> FALSE
A33: P0032 | B33: ياسمين محمود | C33: 5 | D33: Child (0-17) | E33: Female | F33: أنثى | G33: Influenza | H33: أنفلونزا | I33: Respiratory infection | J33: Dr. Khaled Sami | K33: د. خالد سامي | L33: 44992 | M33: 44997 | N33: 5 | O33: 4-7 days | P33: =FALSE() -> FALSE | Q33: =FALSE() -> FALSE | R33: 3 | S33: Mar | T33: Q1 | U33: Tuesday | V33: =FALSE() -> FALSE | W33: Government | X33: تأمين حكومي | Y33: =FALSE() -> FALSE | Z33: High | AA33: مرتفع | AB33: =TRUE() -> TRUE | AD33: 999 | AE33: Placeholder 999 | AG33: =TRUE() -> TRUE
A34: P0033 | B34: محمود إبراهيم | C34: 7 | D34: Child (0-17) | E34: Female | F34: أنثى | G34: Influenza | H34: أنفلونزا | I34: Respiratory infection | J34: Dr. Yasmin Mahmoud | K34: د. ياسمين محمود | L34: 45096 | M34: 45101 | N34: 5 | O34: 4-7 days | P34: =FALSE() -> FALSE | Q34: =FALSE() -> FALSE | R34: 6 | S34: Jun | T34: Q2 | U34: Monday | V34: =FALSE() -> FALSE | W34: Private | X34: تأمين خاص | Y34: =FALSE() -> FALSE | Z34: High | AA34: مرتفع | AB34: =TRUE() -> TRUE | AD34: 3852 | AE34: Placeholder 3852 | AG34: =FALSE() -> FALSE
A35: P0034 | B35: إبراهيم خالد | C35: 16 | D35: Child (0-17) | E35: Female | F35: أنثى | G35: Influenza | H35: أنفلونزا | I35: Respiratory infection | J35: Dr. Ahmed Ali | K35: د. أحمد علي | L35: 45000 | M35: 45008 | N35: 8 | O35: 8-14 days | P35: =TRUE() -> TRUE | Q35: =FALSE() -> FALSE | R35: 3 | S35: Mar | T35: Q1 | U35: Wednesday | V35: =FALSE() -> FALSE | W35: Government | X35: تأمين حكومي | Y35: =FALSE() -> FALSE | Z35: Low | AA35: منخفض | AB35: =FALSE() -> FALSE | AC35: 6551 | AD35: 6551 | AE35: Recorded | AF35: 818.88 | AG35: =FALSE() -> FALSE
A36: P0035 | B36: إبراهيم علي | C36: 34 | D36: Adult (18-39) | E36: Male | F36: ذكر | G36: Influenza | H36: أنفلونزا | I36: Respiratory infection | J36: Dr. Mohamed Hassan | K36: د. محمد حسن | L36: 45163 | M36: 45182 | N36: 19 | O36: 15+ days | P36: =TRUE() -> TRUE | Q36: =TRUE() -> TRUE | R36: 8 | S36: Aug | T36: Q3 | U36: Friday | V36: =TRUE() -> TRUE | W36: Private | X36: تأمين خاص | Y36: =FALSE() -> FALSE | Z36: Medium | AA36: متوسط | AB36: =FALSE() -> FALSE | AD36: 999 | AE36: Placeholder 999 | AG36: =FALSE() -> FALSE | AH36: Long stay for minor condition
A37: P0036 | B37: أحمد خالد | C37: 86 | D37: Senior (60+) | E37: Male | F37: ذكر | G37: Influenza | H37: أنفلونزا | I37: Respiratory infection | J37: Dr. Ahmed Ali | K37: د. أحمد علي | L37: 45246 | M37: 45249 | N37: 3 | O37: 1-3 days | P37: =FALSE() -> FALSE | Q37: =FALSE() -> FALSE | R37: 11 | S37: Nov | T37: Q4 | U37: Thursday | V37: =FALSE() -> FALSE | W37: Uninsured | X37: بدون تأمين | Y37: =TRUE() -> TRUE | Z37: High | AA37: مرتفع | AB37: =TRUE() -> TRUE | AD37: 999 | AE37: Placeholder 999 | AG37: =FALSE() -> FALSE
A38: P0037 | B38: ياسمين علي | C38: 70 | D38: Senior (60+) | E38: Female | F38: أنثى | G38: Influenza | H38: أنفلونزا | I38: Respiratory infection | J38: Dr. Mohamed Hassan | K38: د. محمد حسن | L38: 45281 | M38: 45282 | N38: 1 | O38: 1-3 days | P38: =FALSE() -> FALSE | Q38: =FALSE() -> FALSE | R38: 12 | S38: Dec | T38: Q4 | U38: Thursday | V38: =FALSE() -> FALSE | W38: Government | X38: تأمين حكومي | Y38: =FALSE() -> FALSE | Z38: Medium | AA38: متوسط | AB38: =FALSE() -> FALSE | AD38: 3852 | AE38: Placeholder 3852 | AG38: =TRUE() -> TRUE
A39: P0038 | B39: سارة محمود | C39: 90 | D39: Senior (60+) | E39: Female | F39: أنثى | G39: Influenza | H39: أنفلونزا | I39: Respiratory infection | J39: Dr. Khaled Sami | K39: د. خالد سامي | L39: 45071 | M39: 45076 | N39: 5 | O39: 4-7 days | P39: =FALSE() -> FALSE | Q39: =FALSE() -> FALSE | R39: 5 | S39: May | T39: Q2 | U39: Thursday | V39: =FALSE() -> FALSE | W39: Government | X39: تأمين حكومي | Y39: =FALSE() -> FALSE | Z39: High | AA39: مرتفع | AB39: =TRUE() -> TRUE | AD39: 3852 | AE39: Placeholder 3852 | AG39: =FALSE() -> FALSE
A40: P0039 | B40: مريم إبراهيم | C40: 19 | D40: Adult (18-39) | E40: Female | F40: أنثى | G40: Influenza | H40: أنفلونزا | I40: Respiratory infection | J40: Dr. Yasmin Mahmoud | K40: د. ياسمين محمود | L40: 45235 | M40: 45236 | N40: 1 | O40: 1-3 days | P40: =FALSE() -> FALSE | Q40: =FALSE() -> FALSE | R40: 11 | S40: Nov | T40: Q4 | U40: Sunday | V40: =FALSE() -> FALSE | W40: Uninsured | X40: بدون تأمين | Y40: =TRUE() -> TRUE | Z40: High | AA40: مرتفع | AB40: =TRUE() -> TRUE | AD40: 3852 | AE40: Placeholder 3852 | AG40: =TRUE() -> TRUE
...

Sheet Daily Census
A1: Daily census
A2: Patients occupying a bed each night: admitted on/before the date and discharged after it.
A4: Date | B4: Patients in bed | C4: Admissions that day | D4: Discharges that day
A5: 44926 | B5: =COUNTIFS('Clean Data'!$L$2:$L$248,"<="&A5,'Clean Data'!$M$2:$M$248,">"&A5) -> 1 | C5: =COUNTIFS('Clean Data'!$L$2:$L$248,A5) -> 1 | D5: =COUNTIFS('Clean Data'!$M$2:$M$248,A5) -> 0
A6: 44927 | B6: =COUNTIFS('Clean Data'!$L$2:$L$248,"<="&A6,'Clean Data'!$M$2:$M$248,">"&A6) -> 2 | C6: =COUNTIFS('Clean Data'!$L$2:$L$248,A6) -> 1 | D6: =COUNTIFS('Clean Data'!$M$2:$M$248,A6) -> 0
A7: 44928 | B7: =COUNTIFS('Clean Data'!$L$2:$L$248,"<="&A7,'Clean Data'!$M$2:$M$248,">"&A7) -> 2 | C7: =COUNTIFS('Clean Data'!$L$2:$L$248,A7) -> 0 | D7: =COUNTIFS('Clean Data'!$M$2:$M$248,A7) -> 0
A8: 44929 | B8: =COUNTIFS('Clean Data'!$L$2:$L$248,"<="&A8,'Clean Data'!$M$2:$M$248,">"&A8) -> 1 | C8: =COUNTIFS('Clean Data'!$L$2:$L$248,A8) -> 0 | D8: =COUNTIFS('Clean Data'!$M$2:$M$248,A8) -> 1
A9: 44930 | B9: =COUNTIFS('Clean Data'!$L$2:$L$248,"<="&A9,'Clean Data'!$M$2:$M$248,">"&A9) -> 1 | C9: =COUNTIFS('Clean Data'!$L$2:$L$248,A9) -> 0 | D9: =COUNTIFS('Clean Data'!$M$2:$M$248,A9) -> 0
A10: 44931 | B10: =COUNTIFS('Clean Data'!$L$2:$L$248,"<="&A10,'Clean Data'!$M$2:$M$248,">"&A10) -> 3 | C10: =COUNTIFS('Clean Data'!$L$2:$L$248,A10) -> 3 | D10: =COUNTIFS('Clean Data'!$M$2:$M$248,A10) -> 1
A11: 44932 | B11: =COUNTIFS('Clean Data'!$L$2:$L$248,"<="&A11,'Clean Data'!$M$2:$M$248,">"&A11) -> 5 | C11: =COUNTIFS('Clean Data'!$L$2:$L$248,A11) -> 2 | D11: =COUNTIFS('Clean Data'!$M$2:$M$248,A11) -> 0
A12: 44933 | B12: =COUNTIFS('Clean Data'!$L$2:$L$248,"<="&A12,'Clean Data'!$M$2:$M$248,">"&A12) -> 4 | C12: =COUNTIFS('Clean Data'!$L$2:$L$248,A12) -> 0 | D12: =COUNTIFS('Clean Data'!$M$2:$M$248,A12) -> 1
